Workbook

Sheet دیده بان بازار
A1: Column1 | B1: Column2 | C1: Column3 | D1: Column4 | E1: Column5 | F1: Column6 | G1: Column7 | H1: Column8 | I1: Column9 | J1: Column10 | K1: Column11 | L1: Column12 | M1: Column13 | N1: Column14 | O1: Column15 | P1: Column16 | Q1: Column17 | R1: Column18 | S1: Column19 | T1: Column20 | U1: Column21 | V1: Column22 | W1: Column23
A3: دیده بان بازار : 1405/06/14 - زمان آخرین معامله : 18:00:00
A4: نماد | B4: نام | C4: تعداد | D4: حجم | E4: ارزش | F4: دیروز | G4: اولین | H4: آخرین معامله - مقدار | I4: آخرین معامله - تغییر | J4: آخرین معامله - درصد | K4: قیمت پایانی - مقدار | L4: قیمت پایانی - تغییر | M4: قیمت پایانی - درصد | N4: کمترین | O4: بیشترین | P4: EPS | Q4: P/E | R4: خرید - تعداد | S4: خرید - حجم | T4: خرید - قیمت | U4: فروش - قیمت | V4: فروش - حجم | W4: فروش - تعداد
A5: طملت7047 | B5: اختيارف وبملت-1754-1405/07/22 | C5: 0 | D5: 0 | E5: 0 | F5: 1 | G5: 0 | H5: 1 | I5: 0 | J5: 0 | K5: 1 | L5: 0 | M5: 0 | N5: 0 | O5: 0 | R5: 1 | S5: 55 | T5: 25 | U5: 0 | V5: 0 | W5: 0
A6: طملت7048 | B6: اختيارف وبملت-1854-1405/07/22 | C6: 0 | D6: 0 | E6: 0 | F6: 1 | G6: 0 | H6: 1 | I6: 0 | J6: 0 | K6: 1 | L6: 0 | M6: 0 | N6: 0 | O6: 0 | R6: 1 | S6: 9 | T6: 111 | U6: 0 | V6: 0 | W6: 0
A7: طملت8068 | B7: اختيارف وبملت-800-1405/08/20 | C7: 8 | D7: 3106 | E7: 18860000 | F7: 6 | G7: 8 | H7: 6 | I7: 0 | J7: 0 | K7: 6 | L7: 0 | M7: 0 | N7: 6 | O7: 10 | R7: 1 | S7: 1000 | T7: 3 | U7: 9 | V7: 100 | W7: 1
A8: طملت8069 | B8: اختيارف وبملت-900-1405/08/20 | C8: 0 | D8: 0 | E8: 0 | F8: 15 | G8: 0 | H8: 15 | I8: 0 | J8: 0 | K8: 15 | L8: 0 | M8: 0 | N8: 0 | O8: 0 | R8: 1 | S8: 100 | T8: 4 | U8: 15 | V8: 462 | W8: 1
A9: طملت8070 | B9: اختيارف وبملت-1000-1405/08/20 | C9: 4 | D9: 1051 | E9: 26685000 | F9: 34 | G9: 38 | H9: 25 | I9: -9 | J9: -26.47 | K9: 25 | L9: -9 | M9: -26.47 | N9: 25 | O9: 38 | R9: 1 | S9: 120 | T9: 22 | U9: 25 | V9: 999 | W9: 1
A10: طملت8071 | B10: اختيارف وبملت-1100-1405/08/20 | C10: 0 | D10: 0 | E10: 0 | F10: 1 | G10: 0 | H10: 1 | I10: 0 | J10: 0 | K10: 1 | L10: 0 | M10: 0 | N10: 0 | O10: 0 | R10: 1 | S10: 333 | T10: 3 | U10: 89 | V10: 300 | W10: 1
A11: طملت8072 | B11: اختيارف وبملت-1200-1405/08/20 | C11: 0 | D11: 0 | E11: 0 | F11: 11 | G11: 0 | H11: 11 | I11: 0 | J11: 0 | K11: 11 | L11: 0 | M11: 0 | N11: 0 | O11: 0 | R11: 1 | S11: 450 | T11: 9 | U11: 97 | V11: 499 | W11: 1
A12: طملت8073 | B12: اختيارف وبملت-1300-1405/08/20 | C12: 0 | D12: 0 | E12: 0 | F12: 100 | G12: 0 | H12: 100 | I12: 0 | J12: 0 | K12: 100 | L12: 0 | M12: 0 | N12: 0 | O12: 0 | R12: 1 | S12: 99 | T12: 15 | U12: 0 | V12: 0 | W12: 0
A13: طملت8074 | B13: اختيارف وبملت-1400-1405/08/20 | C13: 0 | D13: 0 | E13: 0 | F13: 1 | G13: 0 | H13: 1 | I13: 0 | J13: 0 | K13: 1 | L13: 0 | M13: 0 | N13: 0 | O13: 0 | R13: 1 | S13: 25 | T13: 11 | U13: 0 | V13: 0 | W13: 0
A14: طملت8075 | B14: اختيارف وبملت-1500-1405/08/20 | C14: 0 | D14: 0 | E14: 0 | F14: 1 | G14: 0 | H14: 1 | I14: 0 | J14: 0 | K14: 1 | L14: 0 | M14: 0 | N14: 0 | O14: 0 | R14: 1 | S14: 25 | T14: 11 | U14: 0 | V14: 0 | W14: 0
A15: طملت8076 | B15: اختيارف وبملت-1600-1405/08/20 | C15: 0 | D15: 0 | E15: 0 | F15: 1 | G15: 0 | H15: 1 | I15: 0 | J15: 0 | K15: 1 | L15: 0 | M15: 0 | N15: 0 | O15: 0 | R15: 1 | S15: 99 | T15: 15 | U15: 0 | V15: 0 | W15: 0
A16: طملت8077 | B16: اختيارف وبملت-1700-1405/08/20 | C16: 0 | D16: 0 | E16: 0 | F16: 1 | G16: 0 | H16: 1 | I16: 0 | J16: 0 | K16: 1 | L16: 0 | M16: 0 | N16: 0 | O16: 0 | R16: 1 | S16: 99 | T16: 19 | U16: 0 | V16: 0 | W16: 0
... A237: افق معادن07 | B237: مرابحه افق توسعه معادن070817 | C237: 0 | D237: 0 | E237: 0 | F237: 1000000 | G237: 0 | H237: 1000000 | I237: 0 | J237: 0 | K237: 1000000 | L237: 0 | M237: 0 | N237: 0 | O237: 0 | R237: 1 | S237: 5000 | T237: 995000 | U237: 1004950 | V237: 5000 | W237: 1
A238: كپرور | B238: فرآوري زغال سنگ پروده طبس | C238: 1305 | D238: 25156472 | E238: 491656705430 | F238: 19850 | G238: 20440 | H238: 19400 | I238: -450 | J238: -2.27 | K238: 19540 | L238: -310 | M238: -1.56 | N238: 19260 | O238: 20440 | P238: 2597 | Q238: 7.52 | R238: 2 | S238: 6783 | T238: 19390 | U238: 19440 | V238: 19055 | W238: 1
A239: آساس | B239: صندوق س.آسمان آرماني سهام-س | C239: 376 | D239: 1429280 | E239: 155304846651 | F239: 106904 | G239: 107007 | H239: 110111 | I239: 3207 | J239: 3 | K239: 108659 | L239: 1755 | M239: 1.64 | N239: 107007 | O239: 110111 | R239: 1 | S239: 60 | T239: 109566 | U239: 112785 | V239: 3000 | W239: 1
A240: اتوداريوش | B240: صندوق س. بخشي داريوش2-ب | C240: 119 | D240: 3122112 | E240: 48800964227 | F240: 15239 | G240: 15696 | H240: 15696 | I240: 457 | J240: 3 | K240: 15631 | L240: 392 | M240: 2.57 | N240: 15200 | O240: 15696 | R240: 2 | S240: 18906 | T240: 15410 | U240: 0 | V240: 0 | W240: 0
A241: امرالد | B241: صندوق س. كالاي كيميا | C241: 4063 | D241: 36114893 | E241: 1121366450464 | F241: 30176 | G241: 30750 | H241: 30967 | I241: 791 | J241: 2.62 | K241: 31050 | L241: 874 | M241: 2.9 | N241: 30750 | O241: 31505 | R241: 1 | S241: 19835 | T241: 30957 | U241: 30967 | V241: 74811 | W241: 1
A242: مشهد0720 | B242: مشاركت ش مشهد0720-3ماهه23% | C242: 0 | D242: 0 | E242: 0 | F242: 1000000 | G242: 0 | H242: 1000000 | I242: 0 | J242: 0 | K242: 1000000 | L242: 0 | M242: 0 | N242: 0 | O242: 0 | R242: 1 | S242: 8000 | T242: 1000000 | U242: 0 | V242: 0 | W242: 0
A243: وپست | B243: پست بانك ايران | C243: 969 | D243: 13694311 | E243: 134530798670 | F243: 9960 | G243: 9900 | H243: 9850 | I243: -110 | J243: -1.1 | K243: 9820 | L243: -140 | M243: -1.41 | N243: 9670 | O243: 10230 | P243: 2033 | Q243: 4.83 | R243: 1 | S243: 10000 | T243: 9830 | U243: 9850 | V243: 114008 | W243: 3
A244: هماي | B244: صندوق س هماي آگاه-ثابت | C244: 3082 | D244: 138211445 | E244: 1401442867905 | F244: 10147 | G244: 10162 | H244: 10143 | I244: -4 | J244: -0.04 | K244: 10140 | L244: -7 | M244: -0.07 | N244: 10130 | O244: 10162 | R244: 13 | S244: 363045 | T244: 10141 | U244: 10143 | V244: 386404 | W244: 2
A245: پلوله | B245: گازلوله‌ | C245: 22 | D245: 1363508 | E245: 12503368360 | F245: 8910 | G245: 9170 | H245: 9170 | I245: 260 | J245: 2.92 | K245: 9140 | L245: 230 | M245: 2.58 | N245: 9170 | O245: 9170 | P245: 517 | Q245: 17.68 | R245: 28 | S245: 5217621 | T245: 9170 | U245: 0 | V245: 0 | W245: 0
A246: آسال | B246: ص.س.درآمد ثابت آسال-د | C246: 278 | D246: 92378591 | E246: 989084263899 | F246: 10684 | G246: 10707 | H246: 10707 | I246: 23 | J246: 0.22 | K246: 10707 | L246: 23 | M246: 0.22 | N246: 10705 | O246: 10708 | R246: 2 | S246: 200000000 | T246: 10707 | U246: 10708 | V246: 8000000 | W246: 8
A247: مزه | B247: صندوق س صنايع دايا3-بخشي | C247: 656 | D247: 9086847 | E247: 257921604111 | F247: 27800 | G247: 28400 | H247: 28399 | I247: 599 | J247: 2.15 | K247: 28384 | L247: 584 | M247: 2.1 | N247: 27999 | O247: 28625 | R247: 1 | S247: 2735 | T247: 28399 | U247: 28402 | V247: 4212 | W247: 1
A248: لذيذ | B248: صندوق س صنايع سينا1-بخشي | C248: 296 | D248: 2697311 | E248: 68571299977 | F248: 25638 | G248: 25030 | H248: 25735 | I248: 97 | J248: 0.38 | K248: 25422 | L248: -216 | M248: -0.84 | N248: 24871 | O248: 26215 | R248: 1 | S248: 23125 | T248: 25629 | U248: 25735 | V248: 4016 | W248: 1
A249: تيپيكو | B249: سرمايه گذاري دارويي تامين | C249: 1466 | D249: 27805733 | E249: 756561343960 | F249: 26450 | G249: 27240 | H249: 27240 | I249: 790 | J249: 2.99 | K249: 27210 | L249: 760 | M249: 2.87 | N249: 26870 | O249: 27240 | P249: 2102 | Q249: 12.94 | R249: 183 | S249: 7469627 | T249: 27240 | U249: 0 | V249: 0 | W249: 0
A250: شاروم3 | B250: پتروشيمي اروميه | C250: 9 | D250: 7950 | E250: 106450500 | F250: 13000 | G250: 13390 | H250: 13390 | I250: 390 | J250: 3 | K250: 13390 | L250: 390 | M250: 3 | N250: 13390 | O250: 13390 | P250: 1318 | Q250: 10.16 | R250: 13 | S250: 177187 | T250: 13390 | U250: 0 | V250: 0 | W250: 0
A251: عبيلت1 | B251: سلف شمش بيلت فولاد خوزستان | C251: 0 | D251: 0 | E251: 0 | F251: 5100000 | G251: 0 | H251: 5100000 | I251: 0 | J251: 0 | K251: 5100000 | L251: 0 | M251: 0 | N251: 0 | O251: 0 | R251: 1 | S251: 49780 | T251: 5000000 | U251: 5100000 | V251: 49961 | W251: 1
A252: ثاميد3 | B252: توسعه و عمران اميد | C252: 8 | D252: 15402 | E252: 27076716 | F252: 1755 | G252: 1758 | H252: 1758 | I252: 3 | J252: 0.17 | K252: 1758 | L252: 3 | M252: 0.17 | N252: 1758 | O252: 1758 | P252: 547 | Q252: 3.21 | R252: 3 | S252: 150388 | T252: 1758 | U252: 0 | V252: 0 | W252: 0
A253: كياصنعت08 | B253: مرابحه كيا صنعت كاران080428 | C253: 0 | D253: 0 | E253: 0 | F253: 1000000 | G253: 0 | H253: 1000000 | I253: 0 | J253: 0 | K253: 1000000 | L253: 0 | M253: 0 | N253: 0 | O253: 0 | R253: 1 | S253: 10000 | T253: 990000 | U253: 1000000 | V253: 10000 | W253: 1
A254: كوير3 | B254: توليدي فولاد سپيد فراب كوير | C254: 224 | D254: 100763000 | E254: 191651226000 | F254: 1847 | G254: 1902 | H254: 1902 | I254: 55 | J254: 2.98 | K254: 1902 | L254: 55 | M254: 2.98 | N254: 1902 | O254: 1902 | P254: 292 | Q254: 6.51 | R254: 363 | S254: 345532738 | T254: 1902 | U254: 0 | V254: 0 | W254: 0
A255: حبندر | B255: دريايي و کشتيراني خط دريابندر | C255: 123 | D255: 1766915 | E255: 14620885830 | F255: 8110 | G255: 8350 | H255: 8350 | I255: 240 | J255: 2.96 | K255: 8270 | L255: 160 | M255: 1.97 | N255: 7950 | O255: 8350 | P255: 1112 | Q255: 7.44 | R255: 1 | S255: 600 | T255: 8350 | U255: 0 | V255: 0 | W255: 0
A256: تابان09 | B256: اجاره تابان فردا نوين14050803 | C256: 0 | D256: 0 | E256: 0 | F256: 988560 | G256: 0 | H256: 977130 | I256: -11430 | J256: -1.16 | K256: 988560 | L256: 0 | M256: 0 | N256: 0 | O256: 0 | R256: 1 | S256: 20000 | T256: 1000000 | U256: 0 | V256: 0 | W256: 0
A257: صگل811 | B257: صكوك مرابحه كگل811-3ماهه23% | C257: 0 | D257: 0 | E257: 0 | F257: 1000000 | G257: 0 | H257: 1000000 | I257: 0 | J257: 0 | K257: 1000000 | L257: 0 | M257: 0 | N257: 0 | O257: 0 | R257: 1 | S257: 10100 | T257: 1000000 | U257: 1000010 | V257: 10000 | W257: 1
A258: توان | B258: صندوق س. اهرمي توان مفيد-س | C258: 13771 | D258: 107822116 | E258: 6058558348000 | F258: 55961 | G258: 57355 | H258: 56432 | I258: 471 | J258: 0.84 | K258: 56190 | L258: 229 | M258: 0.41 | N258: 54275 | O258: 58103 | R258: 2 | S258: 20000 | T258: 56431 | U258: 56432 | V258: 29736 | W258: 1
A259: اكتوور072 | B259: مرابحه اكتوور كو-فارس070612 | C259: 0 | D259: 0 | E259: 0 | F259: 1000000 | G259: 0 | H259: 1000000 | I259: 0 | J259: 0 | K259: 1000000 | L259: 0 | M259: 0 | N259: 0 | O259: 0 | R259: 1 | S259: 10000 | T259: 995000 | U259: 1004950 | V259: 5000 | W259: 1
A260: خليبل | B260: ماليبل سايپا | C260: 64 | D260: 6035318 | E260: 11391366794 | F260: 1941 | G260: 1900 | H260: 1883 | I260: -58 | J260: -2.99 | K260: 1887 | L260: -54 | M260: -2.78 | N260: 1883 | O260: 1900 | P260: -111 | Q260: -17 | R260: 0 | S260: 0 | T260: 0 | U260: 1916 | V260: 15000 | W260: 1
A261: سهگمت | B261: سيمان‌هگمتان‌ | C261: 843 | D261: 1052457 | E261: 141715385400 | F261: 133900 | G261: 137300 | H261: 136000 | I261: 2100 | J261: 1.57 | K261: 134700 | L261: 800 | M261: 0.6 | N261: 133300 | O261: 137900 | P261: 27300 | Q261: 4.93 | R261: 2 | S261: 1552 | T261: 135300 | U261: 136100 | V261: 10150 | W261: 2
...

Sheet انتقال دیده بان
A1: ='دیده بان بازار'!A4 | B1: ='دیده بان بازار'!B4 | C1: ='دیده بان بازار'!C4 | D1: ='دیده بان بازار'!D4 | E1: ='دیده بان بازار'!E4 | F1: ='دیده بان بازار'!F4 | G1: ='دیده بان بازار'!G4 | H1: ='دیده بان بازار'!H4 | ... W1: ='دیده بان بازار'!W4 | X1: مقایسه بهره بری | Y1: نسبت بازدهی مستقیم | Z1: اختلاف قیمت پایانی و کمترین قیمت | AA1: امتیاز کل | AB1: امتیاز موقعیت قیمت کمترین حد پایین نوسان | AC1: رتبه تجمعی حجم معاملات | AD1: امتیاز مقیاس لکاریتمی ارزش معاملات | AE1: موقعیت قیمت آخرین معامله بازه روزانه | AF1: شاخص شتاب فاصله آخرین معامه تا قیمت پایانی | AG1: امتیاز لگاریتمی بهره وری | AH1: ضریب تعدیل و جریمه ریسک افت قیمت | AI1: امتیاز کمکی اختلاف قیمت | AJ1: سیگنال نهائی خرید
A2: ='دیده بان بازار'!A5 | B2: ='دیده بان بازار'!B5 | C2: ='دیده بان بازار'!C5 | D2: ='دیده بان بازار'!D5 | E2: ='دیده بان بازار'!E5 | F2: ='دیده بان بازار'!F5 | G2: ='دیده بان بازار'!G5 | H2: ='دیده بان بازار'!H5 | ... W2: ='دیده بان بازار'!W5 | X2: =IFERROR(IF(OR(R2<=0,W2<=0,S2<=0,V2<=0),0,ROUND((S2/R2)/(V2/W2),2)),0) | Y2: =IFERROR(IF(OR(S2<=0,V2<=0),0,ROUND(S2/V2,2)),0) | Z2: =IFERROR(J2-M2,0) | AA2: =IFERROR(ROUND(MAX(0,MIN(100,((AB2*0.2)+(AC2*0.15)+(AD2*0.15)+(AE2*0.1)+(AF2*0.1)+(AG2*0.15)+(MIN(Y2/3,1)*100*0.1)+(AI2*0.05))*((AH2/100)*0.25+0.75))),0),0) | AB2: =ROUND(MAX(0,MIN(100,((M2+10)/20)*100)),0) | AC2: =IFERROR(IF(D2<=0,0,ROUND(COUNTIFS($D$4:$D$3359,"<="&D2,$D$4:$D$3359,">0")/COUNTIF($D$4:$D$3359,">0")*100,0)),0) | AD2: =IF(E2<=0,0,ROUND(MAX(0,MIN(100,(LOG10(1+E2/1000000000)/LOG10(101))*100)),0)) | AE2: =IF(O2=N2,50,ROUND(MAX(0,MIN(100,((H2-N2)/(O2-N2))*100)),0)) | AF2: =ROUND(MAX(0,MIN(100,50+((H2-K2)/K2)*1000)),0) | AG2: =IFERROR(ROUND(MAX(0,MIN(100,50+25*LN(MAX(0.01,X2)))),0),25) | AH2: =ROUND(IF(M2<=-30,0,IF(M2<=-20,20,IF(M2<=-10,50,100))),0) | AI2: =ROUND(MAX(0,MIN(100,50+(Z2*10))),0) | AJ2: =IFERROR(IF(--AA2>=80,"خرید قوی",IF(--AA2>=70,"خرید مشروط",IF(--AA2>=60,"مراقبت",IF(--AA2>=45,"ضعیف","عدم ورود")))),"")
A3: ='دیده بان بازار'!A6 | B3: ='دیده بان بازار'!B6 | C3: ='دیده بان بازار'!C6 | D3: ='دیده بان بازار'!D6 | E3: ='دیده بان بازار'!E6 | F3: ='دیده بان بازار'!F6 | G3: ='دیده بان بازار'!G6 | H3: ='دیده بان بازار'!H6 | ... W3: ='دیده بان بازار'!W6 | X3: =IFERROR(IF(OR(R3<=0,W3<=0,S3<=0,V3<=0),0,ROUND((S3/R3)/(V3/W3),2)),0) | Y3: =IFERROR(IF(OR(S3<=0,V3<=0),0,ROUND(S3/V3,2)),0) | Z3: =IFERROR(J3-M3,0) | AA3: =IFERROR(ROUND(MAX(0,MIN(100,((AB3*0.2)+(AC3*0.15)+(AD3*0.15)+(AE3*0.1)+(AF3*0.1)+(AG3*0.15)+(MIN(Y3/3,1)*100*0.1)+(AI3*0.05))*((AH3/100)*0.25+0.75))),0),0) | AB3: =ROUND(MAX(0,MIN(100,((M3+10)/20)*100)),0) | AC3: =IFERROR(IF(D3<=0,0,ROUND(COUNTIFS($D$4:$D$3359,"<="&D3,$D$4:$D$3359,">0")/COUNTIF($D$4:$D$3359,">0")*100,0)),0) | AD3: =IF(E3<=0,0,ROUND(MAX(0,MIN(100,(LOG10(1+E3/1000000000)/LOG10(101))*100)),0)) | AE3: =IF(O3=N3,50,ROUND(MAX(0,MIN(100,((H3-N3)/(O3-N3))*100)),0)) | AF3: =ROUND(MAX(0,MIN(100,50+((H3-K3)/K3)*1000)),0) | AG3: =IFERROR(ROUND(MAX(0,MIN(100,50+25*LN(MAX(0.01,X3)))),0),25) | AH3: =ROUND(IF(M3<=-30,0,IF(M3<=-20,20,IF(M3<=-10,50,100))),0) | AI3: =ROUND(MAX(0,MIN(100,50+(Z3*10))),0) | AJ3: =IFERROR(IF(--AA3>=80,"خرید قوی",IF(--AA3>=70,"خرید مشروط",IF(--AA3>=60,"مراقبت",IF(--AA3>=45,"ضعیف","عدم ورود")))),"")
A4: ='دیده بان بازار'!A7 | B4: ='دیده بان بازار'!B7 | C4: ='دیده بان بازار'!C7 | D4: ='دیده بان بازار'!D7 | E4: ='دیده بان بازار'!E7 | F4: ='دیده بان بازار'!F7 | G4: ='دیده بان بازار'!G7 | H4: ='دیده بان بازار'!H7 | ... W4: ='دیده بان بازار'!W7 | X4: =IFERROR(IF(OR(R4<=0,W4<=0,S4<=0,V4<=0),0,ROUND((S4/R4)/(V4/W4),2)),0) | Y4: =IFERROR(IF(OR(S4<=0,V4<=0),0,ROUND(S4/V4,2)),0) | Z4: =IFERROR(J4-M4,0) | AA4: =IFERROR(ROUND(MAX(0,MIN(100,((AB4*0.2)+(AC4*0.15)+(AD4*0.15)+(AE4*0.1)+(AF4*0.1)+(AG4*0.15)+(MIN(Y4/3,1)*100*0.1)+(AI4*0.05))*((AH4/100)*0.25+0.75))),0),0) | AB4: =ROUND(MAX(0,MIN(100,((M4+10)/20)*100)),0) | AC4: =IFERROR(IF(D4<=0,0,ROUND(COUNTIFS($D$4:$D$3359,"<="&D4,$D$4:$D$3359,">0")/COUNTIF($D$4:$D$3359,">0")*100,0)),0) | AD4: =IF(E4<=0,0,ROUND(MAX(0,MIN(100,(LOG10(1+E4/1000000000)/LOG10(101))*100)),0)) | AE4: =IF(O4=N4,50,ROUND(MAX(0,MIN(100,((H4-N4)/(O4-N4))*100)),0)) | AF4: =ROUND(MAX(0,MIN(100,50+((H4-K4)/K4)*1000)),0) | AG4: =IFERROR(ROUND(MAX(0,MIN(100,50+25*LN(MAX(0.01,X4)))),0),25) | AH4: =ROUND(IF(M4<=-30,0,IF(M4<=-20,20,IF(M4<=-10,50,100))),0) | AI4: =ROUND(MAX(0,MIN(100,50+(Z4*10))),0) | AJ4: =IFERROR(IF(--AA4>=80,"خرید قوی",IF(--AA4>=70,"خرید مشروط",IF(--AA4>=60,"مراقبت",IF(--AA4>=45,"ضعیف","عدم ورود")))),"")
A5: ='دیده بان بازار'!A8 | B5: ='دیده بان بازار'!B8 | C5: ='دیده بان بازار'!C8 | D5: ='دیده بان بازار'!D8 | E5: ='دیده بان بازار'!E8 | F5: ='دیده بان بازار'!F8 | G5: ='دیده بان بازار'!G8 | H5: ='دیده بان بازار'!H8 | ... W5: ='دیده بان بازار'!W8 | X5: =IFERROR(IF(OR(R5<=0,W5<=0,S5<=0,V5<=0),0,ROUND((S5/R5)/(V5/W5),2)),0) | Y5: =IFERROR(IF(OR(S5<=0,V5<=0),0,ROUND(S5/V5,2)),0) | Z5: =IFERROR(J5-M5,0) | AA5: =IFERROR(ROUND(MAX(0,MIN(100,((AB5*0.2)+(AC5*0.15)+(AD5*0.15)+(AE5*0.1)+(AF5*0.1)+(AG5*0.15)+(MIN(Y5/3,1)*100*0.1)+(AI5*0.05))*((AH5/100)*0.25+0.75))),0),0) | AB5: =ROUND(MAX(0,MIN(100,((M5+10)/20)*100)),0) | AC5: =IFERROR(IF(D5<=0,0,ROUND(COUNTIFS($D$4:$D$3359,"<="&D5,$D$4:$D$3359,">0")/COUNTIF($D$4:$D$3359,">0")*100,0)),0) | AD5: =IF(E5<=0,0,ROUND(MAX(0,MIN(100,(LOG10(1+E5/1000000000)/LOG10(101))*100)),0)) | AE5: =IF(O5=N5,50,ROUND(MAX(0,MIN(100,((H5-N5)/(O5-N5))*100)),0)) | AF5: =ROUND(MAX(0,MIN(100,50+((H5-K5)/K5)*1000)),0) | AG5: =IFERROR(ROUND(MAX(0,MIN(100,50+25*LN(MAX(0.01,X5)))),0),25) | AH5: =ROUND(IF(M5<=-30,0,IF(M5<=-20,20,IF(M5<=-10,50,100))),0) | AI5: =ROUND(MAX(0,MIN(100,50+(Z5*10))),0) | AJ5: =IFERROR(IF(--AA5>=80,"خرید قوی",IF(--AA5>=70,"خرید مشروط",IF(--AA5>=60,"مراقبت",IF(--AA5>=45,"ضعیف","عدم ورود")))),"")
A6: ='دیده بان بازار'!A9 | B6: ='دیده بان بازار'!B9 | C6: ='دیده بان بازار'!C9 | D6: ='دیده بان بازار'!D9 | E6: ='دیده بان بازار'!E9 | F6: ='دیده بان بازار'!F9 | G6: ='دیده بان بازار'!G9 | H6: ='دیده بان بازار'!H9 | ... W6: ='دیده بان بازار'!W9 | X6: =IFERROR(IF(OR(R6<=0,W6<=0,S6<=0,V6<=0),0,ROUND((S6/R6)/(V6/W6),2)),0) | Y6: =IFERROR(IF(OR(S6<=0,V6<=0),0,ROUND(S6/V6,2)),0) | Z6: =IFERROR(J6-M6,0) | AA6: =IFERROR(ROUND(MAX(0,MIN(100,((AB6*0.2)+(AC6*0.15)+(AD6*0.15)+(AE6*0.1)+(AF6*0.1)+(AG6*0.15)+(MIN(Y6/3,1)*100*0.1)+(AI6*0.05))*((AH6/100)*0.25+0.75))),0),0) | AB6: =ROUND(MAX(0,MIN(100,((M6+10)/20)*100)),0) | AC6: =IFERROR(IF(D6<=0,0,ROUND(COUNTIFS($D$4:$D$3359,"<="&D6,$D$4:$D$3359,">0")/COUNTIF($D$4:$D$3359,">0")*100,0)),0) | AD6: =IF(E6<=0,0,ROUND(MAX(0,MIN(100,(LOG10(1+E6/1000000000)/LOG10(101))*100)),0)) | AE6: =IF(O6=N6,50,ROUND(MAX(0,MIN(100,((H6-N6)/(O6-N6))*100)),0)) | AF6: =ROUND(MAX(0,MIN(100,50+((H6-K6)/K6)*1000)),0) | AG6: =IFERROR(ROUND(MAX(0,MIN(100,50+25*LN(MAX(0.01,X6)))),0),25) | AH6: =ROUND(IF(M6<=-30,0,IF(M6<=-20,20,IF(M6<=-10,50,100))),0) | AI6: =ROUND(MAX(0,MIN(100,50+(Z6*10))),0) | AJ6: =IFERROR(IF(--AA6>=80,"خرید قوی",IF(--AA6>=70,"خرید مشروط",IF(--AA6>=60,"مراقبت",IF(--AA6>=45,"ضعیف","عدم ورود")))),"")
A7: ='دیده بان بازار'!A10 | B7: ='دیده بان بازار'!B10 | C7: ='دیده بان بازار'!C10 | D7: ='دیده بان بازار'!D10 | E7: ='دیده بان بازار'!E10 | F7: ='دیده بان بازار'!F10 | G7: ='دیده بان بازار'!G10 | H7: ='دیده بان بازار'!H10 | ... W7: ='دیده بان بازار'!W10 | X7: =IFERROR(IF(OR(R7<=0,W7<=0,S7<=0,V7<=0),0,ROUND((S7/R7)/(V7/W7),2)),0) | Y7: =IFERROR(IF(OR(S7<=0,V7<=0),0,ROUND(S7/V7,2)),0) | Z7: =IFERROR(J7-M7,0) | AA7: =IFERROR(ROUND(MAX(0,MIN(100,((AB7*0.2)+(AC7*0.15)+(AD7*0.15)+(AE7*0.1)+(AF7*0.1)+(AG7*0.15)+(MIN(Y7/3,1)*100*0.1)+(AI7*0.05))*((AH7/100)*0.25+0.75))),0),0) | AB7: =ROUND(MAX(0,MIN(100,((M7+10)/20)*100)),0) | AC7: =IFERROR(IF(D7<=0,0,ROUND(COUNTIFS($D$4:$D$3359,"<="&D7,$D$4:$D$3359,">0")/COUNTIF($D$4:$D$3359,">0")*100,0)),0) | AD7: =IF(E7<=0,0,ROUND(MAX(0,MIN(100,(LOG10(1+E7/1000000000)/LOG10(101))*100)),0)) | AE7: =IF(O7=N7,50,ROUND(MAX(0,MIN(100,((H7-N7)/(O7-N7))*100)),0)) | AF7: =ROUND(MAX(0,MIN(100,50+((H7-K7)/K7)*1000)),0) | AG7: =IFERROR(ROUND(MAX(0,MIN(100,50+25*LN(MAX(0.01,X7)))),0),25) | AH7: =ROUND(IF(M7<=-30,0,IF(M7<=-20,20,IF(M7<=-10,50,100))),0) | AI7: =ROUND(MAX(0,MIN(100,50+(Z7*10))),0) | AJ7: =IFERROR(IF(--AA7>=80,"خرید قوی",IF(--AA7>=70,"خرید مشروط",IF(--AA7>=60,"مراقبت",IF(--AA7>=45,"ضعیف","عدم ورود")))),"")
A8: ='دیده بان بازار'!A11 | B8: ='دیده بان بازار'!B11 | C8: ='دیده بان بازار'!C11 | D8: ='دیده بان بازار'!D11 | E8: ='دیده بان بازار'!E11 | F8: ='دیده بان بازار'!F11 | G8: ='دیده بان بازار'!G11 | H8: ='دیده بان بازار'!H11 | ... W8: ='دیده بان بازار'!W11 | X8: =IFERROR(IF(OR(R8<=0,W8<=0,S8<=0,V8<=0),0,ROUND((S8/R8)/(V8/W8),2)),0) | Y8: =IFERROR(IF(OR(S8<=0,V8<=0),0,ROUND(S8/V8,2)),0) | Z8: =IFERROR(J8-M8,0) | AA8: =IFERROR(ROUND(MAX(0,MIN(100,((AB8*0.2)+(AC8*0.15)+(AD8*0.15)+(AE8*0.1)+(AF8*0.1)+(AG8*0.15)+(MIN(Y8/3,1)*100*0.1)+(AI8*0.05))*((AH8/100)*0.25+0.75))),0),0) | AB8: =ROUND(MAX(0,MIN(100,((M8+10)/20)*100)),0) | AC8: =IFERROR(IF(D8<=0,0,ROUND(COUNTIFS($D$4:$D$3359,"<="&D8,$D$4:$D$3359,">0")/COUNTIF($D$4:$D$3359,">0")*100,0)),0) | AD8: =IF(E8<=0,0,ROUND(MAX(0,MIN(100,(LOG10(1+E8/1000000000)/LOG10(101))*100)),0)) | AE8: =IF(O8=N8,50,ROUND(MAX(0,MIN(100,((H8-N8)/(O8-N8))*100)),0)) | AF8: =ROUND(MAX(0,MIN(100,50+((H8-K8)/K8)*1000)),0) | AG8: =IFERROR(ROUND(MAX(0,MIN(100,50+25*LN(MAX(0.01,X8)))),0),25) | AH8: =ROUND(IF(M8<=-30,0,IF(M8<=-20,20,IF(M8<=-10,50,100))),0) | AI8: =ROUND(MAX(0,MIN(100,50+(Z8*10))),0) | AJ8: =IFERROR(IF(--AA8>=80,"خرید قوی",IF(--AA8>=70,"خرید مشروط",IF(--AA8>=60,"مراقبت",IF(--AA8>=45,"ضعیف","عدم ورود")))),"")
A9: ='دیده بان بازار'!A12 | B9: ='دیده بان بازار'!B12 | C9: ='دیده بان بازار'!C12 | D9: ='دیده بان بازار'!D12 | E9: ='دیده بان بازار'!E12 | F9: ='دیده بان بازار'!F12 | G9: ='دیده بان بازار'!G12 | H9: ='دیده بان بازار'!H12 | ... W9: ='دیده بان بازار'!W12 | X9: =IFERROR(IF(OR(R9<=0,W9<=0,S9<=0,V9<=0),0,ROUND((S9/R9)/(V9/W9),2)),0) | Y9: =IFERROR(IF(OR(S9<=0,V9<=0),0,ROUND(S9/V9,2)),0) | Z9: =IFERROR(J9-M9,0) | AA9: =IFERROR(ROUND(MAX(0,MIN(100,((AB9*0.2)+(AC9*0.15)+(AD9*0.15)+(AE9*0.1)+(AF9*0.1)+(AG9*0.15)+(MIN(Y9/3,1)*100*0.1)+(AI9*0.05))*((AH9/100)*0.25+0.75))),0),0) | AB9: =ROUND(MAX(0,MIN(100,((M9+10)/20)*100)),0) | AC9: =IFERROR(IF(D9<=0,0,ROUND(COUNTIFS($D$4:$D$3359,"<="&D9,$D$4:$D$3359,">0")/COUNTIF($D$4:$D$3359,">0")*100,0)),0) | AD9: =IF(E9<=0,0,ROUND(MAX(0,MIN(100,(LOG10(1+E9/1000000000)/LOG10(101))*100)),0)) | AE9: =IF(O9=N9,50,ROUND(MAX(0,MIN(100,((H9-N9)/(O9-N9))*100)),0)) | AF9: =ROUND(MAX(0,MIN(100,50+((H9-K9)/K9)*1000)),0) | AG9: =IFERROR(ROUND(MAX(0,MIN(100,50+25*LN(MAX(0.01,X9)))),0),25) | AH9: =ROUND(IF(M9<=-30,0,IF(M9<=-20,20,IF(M9<=-10,50,100))),0) | AI9: =ROUND(MAX(0,MIN(100,50+(Z9*10))),0) | AJ9: =IFERROR(IF(--AA9>=80,"خرید قوی",IF(--AA9>=70,"خرید مشروط",IF(--AA9>=60,"مراقبت",IF(--AA9>=45,"ضعیف","عدم ورود")))),"")
A10: ='دیده بان بازار'!A13 | B10: ='دیده بان بازار'!B13 | C10: ='دیده بان بازار'!C13 | D10: ='دیده بان بازار'!D13 | E10: ='دیده بان بازار'!E13 | F10: ='دیده بان بازار'!F13 | G10: ='دیده بان بازار'!G13 | H10: ='دیده بان بازار'!H13 | ... W10: ='دیده بان بازار'!W13 | X10: =IFERROR(IF(OR(R10<=0,W10<=0,S10<=0,V10<=0),0,ROUND((S10/R10)/(V10/W10),2)),0) | Y10: =IFERROR(IF(OR(S10<=0,V10<=0),0,ROUND(S10/V10,2)),0) | Z10: =IFERROR(J10-M10,0) | AA10: =IFERROR(ROUND(MAX(0,MIN(100,((AB10*0.2)+(AC10*0.15)+(AD10*0.15)+(AE10*0.1)+(AF10*0.1)+(AG10*0.15)+(MIN(Y10/3,1)*100*0.1)+(AI10*0.05))*((AH10/100)*0.25+0.75))),0),0) | AB10: =ROUND(MAX(0,MIN(100,((M10+10)/20)*100)),0) | AC10: =IFERROR(IF(D10<=0,0,ROUND(COUNTIFS($D$4:$D$3359,"<="&D10,$D$4:$D$3359,">0")/COUNTIF($D$4:$D$3359,">0")*100,0)),0) | AD10: =IF(E10<=0,0,ROUND(MAX(0,MIN(100,(LOG10(1+E10/1000000000)/LOG10(101))*100)),0)) | AE10: =IF(O10=N10,50,ROUND(MAX(0,MIN(100,((H10-N10)/(O10-N10))*100)),0)) | AF10: =ROUND(MAX(0,MIN(100,50+((H10-K10)/K10)*1000)),0) | AG10: =IFERROR(ROUND(MAX(0,MIN(100,50+25*LN(MAX(0.01,X10)))),0),25) | AH10: =ROUND(IF(M10<=-30,0,IF(M10<=-20,20,IF(M10<=-10,50,100))),0) | AI10: =ROUND(MAX(0,MIN(100,50+(Z10*10))),0) | AJ10: =IFERROR(IF(--AA10>=80,"خرید قوی",IF(--AA10>=70,"خرید مشروط",IF(--AA10>=60,"مراقبت",IF(--AA10>=45,"ضعیف","عدم ورود")))),"")
A11: ='دیده بان بازار'!A14 | B11: ='دیده بان بازار'!B14 | C11: ='دیده بان بازار'!C14 | D11: ='دیده بان بازار'!D14 | E11: ='دیده بان بازار'!E14 | F11: ='دیده بان بازار'!F14 | G11: ='دیده بان بازار'!G14 | H11: ='دیده بان بازار'!H14 | ... W11: ='دیده بان بازار'!W14 | X11: =IFERROR(IF(OR(R11<=0,W11<=0,S11<=0,V11<=0),0,ROUND((S11/R11)/(V11/W11),2)),0) | Y11: =IFERROR(IF(OR(S11<=0,V11<=0),0,ROUND(S11/V11,2)),0) | Z11: =IFERROR(J11-M11,0) | AA11: =IFERROR(ROUND(MAX(0,MIN(100,((AB11*0.2)+(AC11*0.15)+(AD11*0.15)+(AE11*0.1)+(AF11*0.1)+(AG11*0.15)+(MIN(Y11/3,1)*100*0.1)+(AI11*0.05))*((AH11/100)*0.25+0.75))),0),0) | AB11: =ROUND(MAX(0,MIN(100,((M11+10)/20)*100)),0) | AC11: =IFERROR(IF(D11<=0,0,ROUND(COUNTIFS($D$4:$D$3359,"<="&D11,$D$4:$D$3359,">0")/COUNTIF($D$4:$D$3359,">0")*100,0)),0) | AD11: =IF(E11<=0,0,ROUND(MAX(0,MIN(100,(LOG10(1+E11/1000000000)/LOG10(101))*100)),0)) | AE11: =IF(O11=N11,50,ROUND(MAX(0,MIN(100,((H11-N11)/(O11-N11))*100)),0)) | AF11: =ROUND(MAX(0,MIN(100,50+((H11-K11)/K11)*1000)),0) | AG11: =IFERROR(ROUND(MAX(0,MIN(100,50+25*LN(MAX(0.01,X11)))),0),25) | AH11: =ROUND(IF(M11<=-30,0,IF(M11<=-20,20,IF(M11<=-10,50,100))),0) | AI11: =ROUND(MAX(0,MIN(100,50+(Z11*10))),0) | AJ11: =IFERROR(IF(--AA11>=80,"خرید قوی",IF(--AA11>=70,"خرید مشروط",IF(--AA11>=60,"مراقبت",IF(--AA11>=45,"ضعیف","عدم ورود")))),"")
A12: ='دیده بان بازار'!A15 | B12: ='دیده بان بازار'!B15 | C12: ='دیده بان بازار'!C15 | D12: ='دیده بان بازار'!D15 | E12: ='دیده بان بازار'!E15 | F12: ='دیده بان بازار'!F15 | G12: ='دیده بان بازار'!G15 | H12: ='دیده بان بازار'!H15 | ... W12: ='دیده بان بازار'!W15 | X12: =IFERROR(IF(OR(R12<=0,W12<=0,S12<=0,V12<=0),0,ROUND((S12/R12)/(V12/W12),2)),0) | Y12: =IFERROR(IF(OR(S12<=0,V12<=0),0,ROUND(S12/V12,2)),0) | Z12: =IFERROR(J12-M12,0) | AA12: =IFERROR(ROUND(MAX(0,MIN(100,((AB12*0.2)+(AC12*0.15)+(AD12*0.15)+(AE12*0.1)+(AF12*0.1)+(AG12*0.15)+(MIN(Y12/3,1)*100*0.1)+(AI12*0.05))*((AH12/100)*0.25+0.75))),0),0) | AB12: =ROUND(MAX(0,MIN(100,((M12+10)/20)*100)),0) | AC12: =IFERROR(IF(D12<=0,0,ROUND(COUNTIFS($D$4:$D$3359,"<="&D12,$D$4:$D$3359,">0")/COUNTIF($D$4:$D$3359,">0")*100,0)),0) | AD12: =IF(E12<=0,0,ROUND(MAX(0,MIN(100,(LOG10(1+E12/1000000000)/LOG10(101))*100)),0)) | AE12: =IF(O12=N12,50,ROUND(MAX(0,MIN(100,((H12-N12)/(O12-N12))*100)),0)) | AF12: =ROUND(MAX(0,MIN(100,50+((H12-K12)/K12)*1000)),0) | AG12: =IFERROR(ROUND(MAX(0,MIN(100,50+25*LN(MAX(0.01,X12)))),0),25) | AH12: =ROUND(IF(M12<=-30,0,IF(M12<=-20,20,IF(M12<=-10,50,100))),0) | AI12: =ROUND(MAX(0,MIN(100,50+(Z12*10))),0) | AJ12: =IFERROR(IF(--AA12>=80,"خرید قوی",IF(--AA12>=70,"خرید مشروط",IF(--AA12>=60,"مراقبت",IF(--AA12>=45,"ضعیف","عدم ورود")))),"")
A13: ='دیده بان بازار'!A16 | B13: ='دیده بان بازار'!B16 | C13: ='دیده بان بازار'!C16 | D13: ='دیده بان بازار'!D16 | E13: ='دیده بان بازار'!E16 | F13: ='دیده بان بازار'!F16 | G13: ='دیده بان بازار'!G16 | H13: ='دیده بان بازار'!H16 | ... W13: ='دیده بان بازار'!W16 | X13: =IFERROR(IF(OR(R13<=0,W13<=0,S13<=0,V13<=0),0,ROUND((S13/R13)/(V13/W13),2)),0) | Y13: =IFERROR(IF(OR(S13<=0,V13<=0),0,ROUND(S13/V13,2)),0) | Z13: =IFERROR(J13-M13,0) | AA13: =IFERROR(ROUND(MAX(0,MIN(100,((AB13*0.2)+(AC13*0.15)+(AD13*0.15)+(AE13*0.1)+(AF13*0.1)+(AG13*0.15)+(MIN(Y13/3,1)*100*0.1)+(AI13*0.05))*((AH13/100)*0.25+0.75))),0),0) | AB13: =ROUND(MAX(0,MIN(100,((M13+10)/20)*100)),0) | AC13: =IFERROR(IF(D13<=0,0,ROUND(COUNTIFS($D$4:$D$3359,"<="&D13,$D$4:$D$3359,">0")/COUNTIF($D$4:$D$3359,">0")*100,0)),0) | AD13: =IF(E13<=0,0,ROUND(MAX(0,MIN(100,(LOG10(1+E13/1000000000)/LOG10(101))*100)),0)) | AE13: =IF(O13=N13,50,ROUND(MAX(0,MIN(100,((H13-N13)/(O13-N13))*100)),0)) | AF13: =ROUND(MAX(0,MIN(100,50+((H13-K13)/K13)*1000)),0) | AG13: =IFERROR(ROUND(MAX(0,MIN(100,50+25*LN(MAX(0.01,X13)))),0),25) | AH13: =ROUND(IF(M13<=-30,0,IF(M13<=-20,20,IF(M13<=-10,50,100))),0) | AI13: =ROUND(MAX(0,MIN(100,50+(Z13*10))),0) | AJ13: =IFERROR(IF(--AA13>=80,"خرید قوی",IF(--AA13>=70,"خرید مشروط",IF(--AA13>=60,"مراقبت",IF(--AA13>=45,"ضعیف","عدم ورود")))),"")
... A3356: ='دیده بان بازار'!A3359 | B3356: ='دیده بان بازار'!B3359 | C3356: ='دیده بان بازار'!C3359 | D3356: ='دیده بان بازار'!D3359 | E3356: ='دیده بان بازار'!E3359 | F3356: ='دیده بان بازار'!F3359 | G3356: ='دیده بان بازار'!G3359 | H3356: ='دیده بان بازار'!H3359 | ... W3356: ='دیده بان بازار'!W3359 | X3356: =IFERROR(IF(OR(R3356<=0,W3356<=0,S3356<=0,V3356<=0),0,ROUND((S3356/R3356)/(V3356/W3356),2)),0) | Y3356: =IFERROR(IF(OR(S3356<=0,V3356<=0),0,ROUND(S3356/V3356,2)),0) | Z3356: =IFERROR(J3356-M3356,0) | AA3356: =IFERROR(ROUND(MAX(0,MIN(100,((AB3356*0.2)+(AC3356*0.15)+(AD3356*0.15)+(AE3356*0.1)+(AF3356*0.1)+(AG3356*0.15)+(MIN(Y3356/3,1)*100*0.1)+(AI3356*0.05))*((AH3356/100)*0.25+0.75))),0),0) | AB3356: =ROUND(MAX(0,MIN(100,((M3356+10)/20)*100)),0) | AC3356: =IFERROR(IF(D3356<=0,0,ROUND(COUNTIFS($D$4:$D$3359,"<="&D3356,$D$4:$D$3359,">0")/COUNTIF($D$4:$D$3359,">0")*100,0)),0) | AD3356: =IF(E3356<=0,0,ROUND(MAX(0,MIN(100,(LOG10(1+E3356/1000000000)/LOG10(101))*100)),0)) | AE3356: =IF(O3356=N3356,50,ROUND(MAX(0,MIN(100,((H3356-N3356)/(O3356-N3356))*100)),0)) | AF3356: =ROUND(MAX(0,MIN(100,50+((H3356-K3356)/K3356)*1000)),0) | AG3356: =IFERROR(ROUND(MAX(0,MIN(100,50+25*LN(MAX(0.01,X3356)))),0),25) | AH3356: =ROUND(IF(M3356<=-30,0,IF(M3356<=-20,20,IF(M3356<=-10,50,100))),0) | AI3356: =ROUND(MAX(0,MIN(100,50+(Z3356*10))),0) | AJ3356: =IFERROR(IF(--AA3356>=80,"خرید قوی",IF(--AA3356>=70,"خرید مشروط",IF(--AA3356>=60,"مراقبت",IF(--AA3356>=45,"ضعیف","عدم ورود")))),"")
A3357: ='دیده بان بازار'!A3360 | B3357: ='دیده بان بازار'!B3360 | C3357: ='دیده بان بازار'!C3360 | D3357: ='دیده بان بازار'!D3360 | E3357: ='دیده بان بازار'!E3360 | F3357: ='دیده بان بازار'!F3360 | G3357: ='دیده بان بازار'!G3360 | H3357: ='دیده بان بازار'!H3360 | ... W3357: ='دیده بان بازار'!W3360
A3358: ='دیده بان بازار'!A3361 | B3358: ='دیده بان بازار'!B3361 | C3358: ='دیده بان بازار'!C3361 | D3358: ='دیده بان بازار'!D3361 | E3358: ='دیده بان بازار'!E3361 | F3358: ='دیده بان بازار'!F3361 | G3358: ='دیده بان بازار'!G3361 | H3358: ='دیده بان بازار'!H3361 | ... W3358: ='دیده بان بازار'!W3361
A3359: ='دیده بان بازار'!A3362 | B3359: ='دیده بان بازار'!B3362 | C3359: ='دیده بان بازار'!C3362 | D3359: ='دیده بان بازار'!D3362 | E3359: ='دیده بان بازار'!E3362 | F3359: ='دیده بان بازار'!F3362 | G3359: ='دیده بان بازار'!G3362 | H3359: ='دیده بان بازار'!H3362 | ... W3359: ='دیده بان بازار'!W3362
A3360: ='دیده بان بازار'!A3363 | B3360: ='دیده بان بازار'!B3363 | C3360: ='دیده بان بازار'!C3363 | D3360: ='دیده بان بازار'!D3363 | E3360: ='دیده بان بازار'!E3363 | F3360: ='دیده بان بازار'!F3363 | G3360: ='دیده بان بازار'!G3363 | H3360: ='دیده بان بازار'!H3363 | ... W3360: ='دیده بان بازار'!W3363
A3361: ='دیده بان بازار'!A3364 | B3361: ='دیده بان بازار'!B3364 | C3361: ='دیده بان بازار'!C3364 | D3361: ='دیده بان بازار'!D3364 | E3361: ='دیده بان بازار'!E3364 | F3361: ='دیده بان بازار'!F3364 | G3361: ='دیده بان بازار'!G3364 | H3361: ='دیده بان بازار'!H3364 | ... W3361: ='دیده بان بازار'!W3364
A3362: ='دیده بان بازار'!A3365 | B3362: ='دیده بان بازار'!B3365 | C3362: ='دیده بان بازار'!C3365 | D3362: ='دیده بان بازار'!D3365 | E3362: ='دیده بان بازار'!E3365 | F3362: ='دیده بان بازار'!F3365 | G3362: ='دیده بان بازار'!G3365 | H3362: ='دیده بان بازار'!H3365 | ... W3362: ='دیده بان بازار'!W3365
A3363: ='دیده بان بازار'!A3366 | B3363: ='دیده بان بازار'!B3366 | C3363: ='دیده بان بازار'!C3366 | D3363: ='دیده بان بازار'!D3366 | E3363: ='دیده بان بازار'!E3366 | F3363: ='دیده بان بازار'!F3366 | G3363: ='دیده بان بازار'!G3366 | H3363: ='دیده بان بازار'!H3366 | ... W3363: ='دیده بان بازار'!W3366
A3364: ='دیده بان بازار'!A3367 | B3364: ='دیده بان بازار'!B3367 | C3364: ='دیده بان بازار'!C3367 | D3364: ='دیده بان بازار'!D3367 | E3364: ='دیده بان بازار'!E3367 | F3364: ='دیده بان بازار'!F3367 | G3364: ='دیده بان بازار'!G3367 | H3364: ='دیده بان بازار'!H3367 | ... W3364: ='دیده بان بازار'!W3367
A3365: ='دیده بان بازار'!A3368 | B3365: ='دیده بان بازار'!B3368 | C3365: ='دیده بان بازار'!C3368 | D3365: ='دیده بان بازار'!D3368 | E3365: ='دیده بان بازار'!E3368 | F3365: ='دیده بان بازار'!F3368 | G3365: ='دیده بان بازار'!G3368 | H3365: ='دیده بان بازار'!H3368 | ... W3365: ='دیده بان بازار'!W3368
A3366: ='دیده بان بازار'!A3369 | B3366: ='دیده بان بازار'!B3369 | C3366: ='دیده بان بازار'!C3369 | D3366: ='دیده بان بازار'!D3369 | E3366: ='دیده بان بازار'!E3369 | F3366: ='دیده بان بازار'!F3369 | G3366: ='دیده بان بازار'!G3369 | H3366: ='دیده بان بازار'!H3369 | ... W3366: ='دیده بان بازار'!W3369
A3367: ='دیده بان بازار'!A3370 | B3367: ='دیده بان بازار'!B3370 | C3367: ='دیده بان بازار'!C3370 | D3367: ='دیده بان بازار'!D3370 | E3367: ='دیده بان بازار'!E3370 | F3367: ='دیده بان بازار'!F3370 | G3367: ='دیده بان بازار'!G3370 | H3367: ='دیده بان بازار'!H3370 | ... W3367: ='دیده بان بازار'!W3370
A3368: ='دیده بان بازار'!A3371 | B3368: ='دیده بان بازار'!B3371 | C3368: ='دیده بان بازار'!C3371 | D3368: ='دیده بان بازار'!D3371 | E3368: ='دیده بان بازار'!E3371 | F3368: ='دیده بان بازار'!F3371 | G3368: ='دیده بان بازار'!G3371 | H3368: ='دیده بان بازار'!H3371 | ... W3368: ='دیده بان بازار'!W3371
... A3382: ='دیده بان بازار'!A3385 | B3382: ='دیده بان بازار'!B3385 | C3382: ='دیده بان بازار'!C3385 | D3382: ='دیده بان بازار'!D3385 | E3382: ='دیده بان بازار'!E3385 | F3382: ='دیده بان بازار'!F3385 | G3382: ='دیده بان بازار'!G3385 | H3382: ='دیده بان بازار'!H3385 | ... W3382: ='دیده بان بازار'!W3385
A3383: ='دیده بان بازار'!#REF! | B3383: ='دیده بان بازار'!#REF! | C3383: ='دیده بان بازار'!#REF! | D3383: ='دیده بان بازار'!#REF! | E3383: ='دیده بان بازار'!#REF! | F3383: ='دیده بان بازار'!#REF! | G3383: ='دیده بان بازار'!#REF! | H3383: ='دیده بان بازار'!#REF! | ... W3383: ='دیده بان بازار'!#REF!
A3384: ='دیده بان بازار'!#REF! | B3384: ='دیده بان بازار'!#REF! | C3384: ='دیده بان بازار'!#REF! | D3384: ='دیده بان بازار'!#REF! | E3384: ='دیده بان بازار'!#REF! | F3384: ='دیده بان بازار'!#REF! | G3384: ='دیده بان بازار'!#REF! | H3384: ='دیده بان بازار'!#REF! | ... W3384: ='دیده بان بازار'!#REF!
A3385: ='دیده بان بازار'!#REF! | B3385: ='دیده بان بازار'!#REF! | C3385: ='دیده بان بازار'!#REF! | D3385: ='دیده بان بازار'!#REF! | E3385: ='دیده بان بازار'!#REF! | F3385: ='دیده بان بازار'!#REF! | G3385: ='دیده بان بازار'!#REF! | H3385: ='دیده بان بازار'!#REF! | ... W3385: ='دیده بان بازار'!#REF!
A3386: ='دیده بان بازار'!#REF! | B3386: ='دیده بان بازار'!#REF! | C3386: ='دیده بان بازار'!#REF! | D3386: ='دیده بان بازار'!#REF! | E3386: ='دیده بان بازار'!#REF! | F3386: ='دیده بان بازار'!#REF! | G3386: ='دیده بان بازار'!#REF! | H3386: ='دیده بان بازار'!#REF! | ... W3386: ='دیده بان بازار'!#REF!
A3387: ='دیده بان بازار'!#REF! | B3387: ='دیده بان بازار'!#REF! | C3387: ='دیده بان بازار'!#REF! | D3387: ='دیده بان بازار'!#REF! | E3387: ='دیده بان بازار'!#REF! | F3387: ='دیده بان بازار'!#REF! | G3387: ='دیده بان بازار'!#REF! | H3387: ='دیده بان بازار'!#REF! | ... W3387: ='دیده بان بازار'!#REF!
A3388: ='دیده بان بازار'!#REF! | B3388: ='دیده بان بازار'!#REF! | C3388: ='دیده بان بازار'!#REF! | D3388: ='دیده بان بازار'!#REF! | E3388: ='دیده بان بازار'!#REF! | F3388: ='دیده بان بازار'!#REF! | G3388: ='دیده بان بازار'!#REF! | H3388: ='دیده بان بازار'!#REF! | ... W3388: ='دیده بان بازار'!#REF!
A3389: ='دیده بان بازار'!#REF! | B3389: ='دیده بان بازار'!#REF! | C3389: ='دیده بان بازار'!#REF! | D3389: ='دیده بان بازار'!#REF! | E3389: ='دیده بان بازار'!#REF! | F3389: ='دیده بان بازار'!#REF! | G3389: ='دیده بان بازار'!#REF! | H3389: ='دیده بان بازار'!#REF! | ... W3389: ='دیده بان بازار'!#REF!
A3390: ='دیده بان بازار'!#REF! | B3390: ='دیده بان بازار'!#REF! | C3390: ='دیده بان بازار'!#REF! | D3390: ='دیده بان بازار'!#REF! | E3390: ='دیده بان بازار'!#REF! | F3390: ='دیده بان بازار'!#REF! | G3390: ='دیده بان بازار'!#REF! | H3390: ='دیده بان بازار'!#REF! | ... W3390: ='دیده بان بازار'!#REF!
A3391: ='دیده بان بازار'!#REF! | B3391: ='دیده بان بازار'!#REF! | C3391: ='دیده بان بازار'!#REF! | D3391: ='دیده بان بازار'!#REF! | E3391: ='دیده بان بازار'!#REF! | F3391: ='دیده بان بازار'!#REF! | G3391: ='دیده بان بازار'!#REF! | H3391: ='دیده بان بازار'!#REF! | ... W3391: ='دیده بان بازار'!#REF!
A3392: ='دیده بان بازار'!#REF! | B3392: ='دیده بان بازار'!#REF! | C3392: ='دیده بان بازار'!#REF! | D3392: ='دیده بان بازار'!#REF! | E3392: ='دیده بان بازار'!#REF! | F3392: ='دیده بان بازار'!#REF! | G3392: ='دیده بان بازار'!#REF! | H3392: ='دیده بان بازار'!#REF! | ... W3392: ='دیده بان بازار'!#REF!
A3393: ='دیده بان بازار'!#REF! | B3393: ='دیده بان بازار'!#REF! | C3393: ='دیده بان بازار'!#REF! | D3393: ='دیده بان بازار'!#REF! | E3393: ='دیده بان بازار'!#REF! | F3393: ='دیده بان بازار'!#REF! | G3393: ='دیده بان بازار'!#REF! | H3393: ='دیده بان بازار'!#REF! | ... W3393: ='دیده بان بازار'!#REF!
A3394: ='دیده بان بازار'!#REF! | B3394: ='دیده بان بازار'!#REF! | C3394: ='دیده بان بازار'!#REF! | D3394: ='دیده بان بازار'!#REF! | E3394: ='دیده بان بازار'!#REF! | F3394: ='دیده بان بازار'!#REF! | G3394: ='دیده بان بازار'!#REF! | H3394: ='دیده بان بازار'!#REF! | ... W3394: ='دیده بان بازار'!#REF!
... A3408: ='دیده بان بازار'!#REF! | B3408: ='دیده بان بازار'!#REF! | C3408: ='دیده بان بازار'!#REF! | D3408: ='دیده بان بازار'!#REF! | E3408: ='دیده بان بازار'!#REF! | F3408: ='دیده بان بازار'!#REF! | G3408: ='دیده بان بازار'!#REF! | H3408: ='دیده بان بازار'!#REF! | ... W3408: ='دیده بان بازار'!#REF!
...

Sheet بررسی 
A1: نماد | B1: نام | C1: تعداد | D1: حجم | E1: ارزش | F1: دیروز | G1: اولین | H1: آخرین معامله - مقدار | I1: آخرین معامله - تغییر | J1: آخرین معامله - درصد | K1: قیمت پایانی - مقدار | L1: قیمت پایانی - تغییر | M1: قیمت پایانی - درصد | N1: کمترین | O1: بیشترین | P1: EPS | Q1: P/E | R1: خرید - تعداد | S1: خرید - حجم | T1: خرید - قیمت | U1: فروش - قیمت | V1: فروش - حجم | W1: فروش - تعداد | X1: 0 | Y1: -
A2: {=_xlfn._xlws.FILTER('انتقال دیده بان'!A4:W3358, ('انتقال دیده بان'!I4:I3358 > 0.5) * ('انتقال دیده بان'!I4:I3358 < 4.5) * ('انتقال دیده بان'!D4:D3358 > 300000) * (IFERROR('انتقال دیده بان'!Q4:Q3358/'انتقال دیده بان'!P4:P3358, 0) > IFERROR('انتقال دیده بان'!T4:T3358/'انتقال دیده بان'!U4:U3358, 0)) * (ISERROR(SEARCH("اختيار", 'انتقال دیده بان'!B4:B3358))), "هیچ نمادی یافت نشد")} | B2: بانك تجارت | C2: 55 | D2: 6616105 | E2: 6503631215 | F2: 982 | G2: 983 | H2: 983 | I2: 1 | J2: 0.1 | K2: 983 | L2: 1 | M2: 0.1 | N2: 983 | O2: 983 | P2: 105 | Q2: 9.36 | R2: 0 | S2: 0 | T2: 0 | U2: 983 | V2: 277185573 | W2: 159

Sheet خروجی شکار نمادهای جامانده 
A1: رتبه | B1: ردیف منبع | C1: نماد | D1: نام شرکت | E1: امتیاز | F1: سیگنال | G1: آخرین % | H1: پایانی % | I1: حجم | J1: ارزش معاملات | K1: نسبت خرید/فروش | L1: میانگین ارزش معامله | M1: موقعیت روز | N1: شتاب | O1: ریسک | P1: اختلاف قیمت | Q1: وضعیت شکار | S1: منبع و منطق
A2: =IF($B2="","",ROWS($A$2:A2)) | B2: =IFERROR(MATCH(IFERROR(AGGREGATE(14,6,(('انتقال دیده بان'!$AA$2:$AA$4926)+ROW('انتقال دیده بان'!$AA$2:$AA$4926)/100000000)/(('انتقال دیده بان'!$A$2:$A$4926<>"")* ('انتقال دیده بان'!$B$2:$B$4926<>"")* ISERROR(SEARCH("صندوق",'انتقال دیده بان'!$B$2:$B$4926))* ISERROR(SEARCH("درآمد ثابت",'انتقال دیده بان'!$B$2:$B$4926))* ISERROR(SEARCH("اختیار",'انتقال دیده بان'!$B$2:$B$4926))* ISERROR(SEARCH("اختيار",'انتقال دیده بان'!$B$2:$B$4926))* ISERROR(SEARCH("حق تقدم",'انتقال دیده بان'!$B$2:$B$4926))* ('انتقال دیده بان'!$AA$2:$AA$4926>=70)* ('انتقال دیده بان'!$J$2:$J$4926>=-0.5)* ('انتقال دیده بان'!$J$2:$J$4926<=1.5)* ('انتقال دیده بان'!$M$2:$M$4926>=-1)* ('انتقال دیده بان'!$M$2:$M$4926<=3.5)* ('انتقال دیده بان'!$D$2:$D$4926>=300000)* ('انتقال دیده بان'!$E$2:$E$4926>=1000000000)* ('انتقال دیده بان'!$Y$2:$Y$4926>=1)* IFERROR(('انتقال دیده بان'!$E$2:$E$4926/'انتقال دیده بان'!$C$2:$C$4926)>=20000000,FALSE)* ('انتقال دیده بان'!$AH$2:$AH$4926>=50)),ROWS($A$2:A2)),0),((('انتقال دیده بان'!$AA$2:$AA$4926)+ROW('انتقال دیده بان'!$AA$2:$AA$4926)/100000000)),0),"") | C2: =IF($B2="","",INDEX('انتقال دیده بان'!$A$2:$A$4926,$B2)) | D2: =IF($B2="","",INDEX('انتقال دیده بان'!$B$2:$B$4926,$B2)) | E2: =IF($B2="","",INDEX('انتقال دیده بان'!$AA$2:$AA$4926,$B2)) | F2: =IF($B2="","",INDEX('انتقال دیده بان'!$AJ$2:$AJ$4926,$B2)) | G2: =IF($B2="","",INDEX('انتقال دیده بان'!$J$2:$J$4926,$B2)) | H2: =IF($B2="","",INDEX('انتقال دیده بان'!$M$2:$M$4926,$B2)) | I2: =IF($B2="","",INDEX('انتقال دیده بان'!$D$2:$D$4926,$B2)) | J2: =IF($B2="","",INDEX('انتقال دیده بان'!$E$2:$E$4926,$B2)) | K2: =IF($B2="","",INDEX('انتقال دیده بان'!$Y$2:$Y$4926,$B2)) | L2: =IF($B2="","",INDEX('انتقال دیده بان'!$X$2:$X$4926,$B2)) | M2: =IF($B2="","",INDEX('انتقال دیده بان'!$AE$2:$AE$4926,$B2)) | N2: =IF($B2="","",INDEX('انتقال دیده بان'!$AF$2:$AF$4926,$B2)) | O2: =IF($B2="","",INDEX('انتقال دیده بان'!$AH$2:$AH$4926,$B2)) | P2: =IF($B2="","",INDEX('انتقال دیده بان'!$AI$2:$AI$4926,$B2)) | Q2: =IF($B2="","",IF($E2>=85,"شکار ممتاز",IF($E2>=80,"شکار قوی","شکار مشروط"))) | S2: منبع داده | T2: انتقال دیده بان ← متصل به دیده بان بازار
A3: =IF($B3="","",ROWS($A$2:A3)) | B3: =IFERROR(MATCH(IFERROR(AGGREGATE(14,6,(('انتقال دیده بان'!$AA$2:$AA$4926)+ROW('انتقال دیده بان'!$AA$2:$AA$4926)/100000000)/(('انتقال دیده بان'!$A$2:$A$4926<>"")* ('انتقال دیده بان'!$B$2:$B$4926<>"")* ISERROR(SEARCH("صندوق",'انتقال دیده بان'!$B$2:$B$4926))* ISERROR(SEARCH("درآمد ثابت",'انتقال دیده بان'!$B$2:$B$4926))* ISERROR(SEARCH("اختیار",'انتقال دیده بان'!$B$2:$B$4926))* ISERROR(SEARCH("اختيار",'انتقال دیده بان'!$B$2:$B$4926))* ISERROR(SEARCH("حق تقدم",'انتقال دیده بان'!$B$2:$B$4926))* ('انتقال دیده بان'!$AA$2:$AA$4926>=70)* ('انتقال دیده بان'!$J$2:$J$4926>=-0.5)* ('انتقال دیده بان'!$J$2:$J$4926<=1.5)* ('انتقال دیده بان'!$M$2:$M$4926>=-1)* ('انتقال دیده بان'!$M$2:$M$4926<=3.5)* ('انتقال دیده بان'!$D$2:$D$4926>=300000)* ('انتقال دیده بان'!$E$2:$E$4926>=1000000000)* ('انتقال دیده بان'!$Y$2:$Y$4926>=1)* IFERROR(('انتقال دیده بان'!$E$2:$E$4926/'انتقال دیده بان'!$C$2:$C$4926)>=20000000,FALSE)* ('انتقال دیده بان'!$AH$2:$AH$4926>=50)),ROWS($A$2:A3)),0),((('انتقال دیده بان'!$AA$2:$AA$4926)+ROW('انتقال دیده بان'!$AA$2:$AA$4926)/100000000)),0),"") | C3: =IF($B3="","",INDEX('انتقال دیده بان'!$A$2:$A$4926,$B3)) | D3: =IF($B3="","",INDEX('انتقال دیده بان'!$B$2:$B$4926,$B3)) | E3: =IF($B3="","",INDEX('انتقال دیده بان'!$AA$2:$AA$4926,$B3)) | F3: =IF($B3="","",INDEX('انتقال دیده بان'!$AJ$2:$AJ$4926,$B3)) | G3: =IF($B3="","",INDEX('انتقال دیده بان'!$J$2:$J$4926,$B3)) | H3: =IF($B3="","",INDEX('انتقال دیده بان'!$M$2:$M$4926,$B3)) | I3: =IF($B3="","",INDEX('انتقال دیده بان'!$D$2:$D$4926,$B3)) | J3: =IF($B3="","",INDEX('انتقال دیده بان'!$E$2:$E$4926,$B3)) | K3: =IF($B3="","",INDEX('انتقال دیده بان'!$Y$2:$Y$4926,$B3)) | L3: =IF($B3="","",INDEX('انتقال دیده بان'!$X$2:$X$4926,$B3)) | M3: =IF($B3="","",INDEX('انتقال دیده بان'!$AE$2:$AE$4926,$B3)) | N3: =IF($B3="","",INDEX('انتقال دیده بان'!$AF$2:$AF$4926,$B3)) | O3: =IF($B3="","",INDEX('انتقال دیده بان'!$AH$2:$AH$4926,$B3)) | P3: =IF($B3="","",INDEX('انتقال دیده بان'!$AI$2:$AI$4926,$B3)) | Q3: =IF($B3="","",IF($E3>=85,"شکار ممتاز",IF($E3>=80,"شکار قوی","شکار مشروط"))) | S3: فیلتر | T3: امتیاز ≥70 + نقدشوندگی + حرکت کنترل‌شده + نسبت خرید/فروش ≥1
A4: =IF($B4="","",ROWS($A$2:A4)) | B4: =IFERROR(MATCH(IFERROR(AGGREGATE(14,6,(('انتقال دیده بان'!$AA$2:$AA$4926)+ROW('انتقال دیده بان'!$AA$2:$AA$4926)/100000000)/(('انتقال دیده بان'!$A$2:$A$4926<>"")* ('انتقال دیده بان'!$B$2:$B$4926<>"")* ISERROR(SEARCH("صندوق",'انتقال دیده بان'!$B$2:$B$4926))* ISERROR(SEARCH("درآمد ثابت",'انتقال دیده بان'!$B$2:$B$4926))* ISERROR(SEARCH("اختیار",'انتقال دیده بان'!$B$2:$B$4926))* ISERROR(SEARCH("اختيار",'انتقال دیده بان'!$B$2:$B$4926))* ISERROR(SEARCH("حق تقدم",'انتقال دیده بان'!$B$2:$B$4926))* ('انتقال دیده بان'!$AA$2:$AA$4926>=70)* ('انتقال دیده بان'!$J$2:$J$4926>=-0.5)* ('انتقال دیده بان'!$J$2:$J$4926<=1.5)* ('انتقال دیده بان'!$M$2:$M$4926>=-1)* ('انتقال دیده بان'!$M$2:$M$4926<=3.5)* ('انتقال دیده بان'!$D$2:$D$4926>=300000)* ('انتقال دیده بان'!$E$2:$E$4926>=1000000000)* ('انتقال دیده بان'!$Y$2:$Y$4926>=1)* IFERROR(('انتقال دیده بان'!$E$2:$E$4926/'انتقال دیده بان'!$C$2:$C$4926)>=20000000,FALSE)* ('انتقال دیده بان'!$AH$2:$AH$4926>=50)),ROWS($A$2:A4)),0),((('انتقال دیده بان'!$AA$2:$AA$4926)+ROW('انتقال دیده بان'!$AA$2:$AA$4926)/100000000)),0),"") | C4: =IF($B4="","",INDEX('انتقال دیده بان'!$A$2:$A$4926,$B4)) | D4: =IF($B4="","",INDEX('انتقال دیده بان'!$B$2:$B$4926,$B4)) | E4: =IF($B4="","",INDEX('انتقال دیده بان'!$AA$2:$AA$4926,$B4)) | F4: =IF($B4="","",INDEX('انتقال دیده بان'!$AJ$2:$AJ$4926,$B4)) | G4: =IF($B4="","",INDEX('انتقال دیده بان'!$J$2:$J$4926,$B4)) | H4: =IF($B4="","",INDEX('انتقال دیده بان'!$M$2:$M$4926,$B4)) | I4: =IF($B4="","",INDEX('انتقال دیده بان'!$D$2:$D$4926,$B4)) | J4: =IF($B4="","",INDEX('انتقال دیده بان'!$E$2:$E$4926,$B4)) | K4: =IF($B4="","",INDEX('انتقال دیده بان'!$Y$2:$Y$4926,$B4)) | L4: =IF($B4="","",INDEX('انتقال دیده بان'!$X$2:$X$4926,$B4)) | M4: =IF($B4="","",INDEX('انتقال دیده بان'!$AE$2:$AE$4926,$B4)) | N4: =IF($B4="","",INDEX('انتقال دیده بان'!$AF$2:$AF$4926,$B4)) | O4: =IF($B4="","",INDEX('انتقال دیده بان'!$AH$2:$AH$4926,$B4)) | P4: =IF($B4="","",INDEX('انتقال دیده بان'!$AI$2:$AI$4926,$B4)) | Q4: =IF($B4="","",IF($E4>=85,"شکار ممتاز",IF($E4>=80,"شکار قوی","شکار مشروط"))) | S4: ممتاز | T4: امتیاز ≥85
A5: =IF($B5="","",ROWS($A$2:A5)) | B5: =IFERROR(MATCH(IFERROR(AGGREGATE(14,6,(('انتقال دیده بان'!$AA$2:$AA$4926)+ROW('انتقال دیده بان'!$AA$2:$AA$4926)/100000000)/(('انتقال دیده بان'!$A$2:$A$4926<>"")* ('انتقال دیده بان'!$B$2:$B$4926<>"")* ISERROR(SEARCH("صندوق",'انتقال دیده بان'!$B$2:$B$4926))* ISERROR(SEARCH("درآمد ثابت",'انتقال دیده بان'!$B$2:$B$4926))* ISERROR(SEARCH("اختیار",'انتقال دیده بان'!$B$2:$B$4926))* ISERROR(SEARCH("اختيار",'انتقال دیده بان'!$B$2:$B$4926))* ISERROR(SEARCH("حق تقدم",'انتقال دیده بان'!$B$2:$B$4926))* ('انتقال دیده بان'!$AA$2:$AA$4926>=70)* ('انتقال دیده بان'!$J$2:$J$4926>=-0.5)* ('انتقال دیده بان'!$J$2:$J$4926<=1.5)* ('انتقال دیده بان'!$M$2:$M$4926>=-1)* ('انتقال دیده بان'!$M$2:$M$4926<=3.5)* ('انتقال دیده بان'!$D$2:$D$4926>=300000)* ('انتقال دیده بان'!$E$2:$E$4926>=1000000000)* ('انتقال دیده بان'!$Y$2:$Y$4926>=1)* IFERROR(('انتقال دیده بان'!$E$2:$E$4926/'انتقال دیده بان'!$C$2:$C$4926)>=20000000,FALSE)* ('انتقال دیده بان'!$AH$2:$AH$4926>=50)),ROWS($A$2:A5)),0),((('انتقال دیده بان'!$AA$2:$AA$4926)+ROW('انتقال دیده بان'!$AA$2:$AA$4926)/100000000)),0),"") | C5: =IF($B5="","",INDEX('انتقال دیده بان'!$A$2:$A$4926,$B5)) | D5: =IF($B5="","",INDEX('انتقال دیده بان'!$B$2:$B$4926,$B5)) | E5: =IF($B5="","",INDEX('انتقال دیده بان'!$AA$2:$AA$4926,$B5)) | F5: =IF($B5="","",INDEX('انتقال دیده بان'!$AJ$2:$AJ$4926,$B5)) | G5: =IF($B5="","",INDEX('انتقال دیده بان'!$J$2:$J$4926,$B5)) | H5: =IF($B5="","",INDEX('انتقال دیده بان'!$M$2:$M$4926,$B5)) | I5: =IF($B5="","",INDEX('انتقال دیده بان'!$D$2:$D$4926,$B5)) | J5: =IF($B5="","",INDEX('انتقال دیده بان'!$E$2:$E$4926,$B5)) | K5: =IF($B5="","",INDEX('انتقال دیده بان'!$Y$2:$Y$4926,$B5)) | L5: =IF($B5="","",INDEX('انتقال دیده بان'!$X$2:$X$4926,$B5)) | M5: =IF($B5="","",INDEX('انتقال دیده بان'!$AE$2:$AE$4926,$B5)) | N5: =IF($B5="","",INDEX('انتقال دیده بان'!$AF$2:$AF$4926,$B5)) | O5: =IF($B5="","",INDEX('انتقال دیده بان'!$AH$2:$AH$4926,$B5)) | P5: =IF($B5="","",INDEX('انتقال دیده بان'!$AI$2:$AI$4926,$B5)) | Q5: =IF($B5="","",IF($E5>=85,"شکار ممتاز",IF($E5>=80,"شکار قوی","شکار مشروط"))) | S5: قوی | T5: امتیاز 80 تا 84
A6: =IF($B6="","",ROWS($A$2:A6)) | B6: =IFERROR(MATCH(IFERROR(AGGREGATE(14,6,(('انتقال دیده بان'!$AA$2:$AA$4926)+ROW('انتقال دیده بان'!$AA$2:$AA$4926)/100000000)/(('انتقال دیده بان'!$A$2:$A$4926<>"")* ('انتقال دیده بان'!$B$2:$B$4926<>"")* ISERROR(SEARCH("صندوق",'انتقال دیده بان'!$B$2:$B$4926))* ISERROR(SEARCH("درآمد ثابت",'انتقال دیده بان'!$B$2:$B$4926))* ISERROR(SEARCH("اختیار",'انتقال دیده بان'!$B$2:$B$4926))* ISERROR(SEARCH("اختيار",'انتقال دیده بان'!$B$2:$B$4926))* ISERROR(SEARCH("حق تقدم",'انتقال دیده بان'!$B$2:$B$4926))* ('انتقال دیده بان'!$AA$2:$AA$4926>=70)* ('انتقال دیده بان'!$J$2:$J$4926>=-0.5)* ('انتقال دیده بان'!$J$2:$J$4926<=1.5)* ('انتقال دیده بان'!$M$2:$M$4926>=-1)* ('انتقال دیده بان'!$M$2:$M$4926<=3.5)* ('انتقال دیده بان'!$D$2:$D$4926>=300000)* ('انتقال دیده بان'!$E$2:$E$4926>=1000000000)* ('انتقال دیده بان'!$Y$2:$Y$4926>=1)* IFERROR(('انتقال دیده بان'!$E$2:$E$4926/'انتقال دیده بان'!$C$2:$C$4926)>=20000000,FALSE)* ('انتقال دیده بان'!$AH$2:$AH$4926>=50)),ROWS($A$2:A6)),0),((('انتقال دیده بان'!$AA$2:$AA$4926)+ROW('انتقال دیده بان'!$AA$2:$AA$4926)/100000000)),0),"") | C6: =IF($B6="","",INDEX('انتقال دیده بان'!$A$2:$A$4926,$B6)) | D6: =IF($B6="","",INDEX('انتقال دیده بان'!$B$2:$B$4926,$B6)) | E6: =IF($B6="","",INDEX('انتقال دیده بان'!$AA$2:$AA$4926,$B6)) | F6: =IF($B6="","",INDEX('انتقال دیده بان'!$AJ$2:$AJ$4926,$B6)) | G6: =IF($B6="","",INDEX('انتقال دیده بان'!$J$2:$J$4926,$B6)) | H6: =IF($B6="","",INDEX('انتقال دیده بان'!$M$2:$M$4926,$B6)) | I6: =IF($B6="","",INDEX('انتقال دیده بان'!$D$2:$D$4926,$B6)) | J6: =IF($B6="","",INDEX('انتقال دیده بان'!$E$2:$E$4926,$B6)) | K6: =IF($B6="","",INDEX('انتقال دیده بان'!$Y$2:$Y$4926,$B6)) | L6: =IF($B6="","",INDEX('انتقال دیده بان'!$X$2:$X$4926,$B6)) | M6: =IF($B6="","",INDEX('انتقال دیده بان'!$AE$2:$AE$4926,$B6)) | N6: =IF($B6="","",INDEX('انتقال دیده بان'!$AF$2:$AF$4926,$B6)) | O6: =IF($B6="","",INDEX('انتقال دیده بان'!$AH$2:$AH$4926,$B6)) | P6: =IF($B6="","",INDEX('انتقال دیده بان'!$AI$2:$AI$4926,$B6)) | Q6: =IF($B6="","",IF($E6>=85,"شکار ممتاز",IF($E6>=80,"شکار قوی","شکار مشروط"))) | S6: مشروط | T6: امتیاز 70 تا 79
A7: =IF($B7="","",ROWS($A$2:A7)) | B7: =IFERROR(MATCH(IFERROR(AGGREGATE(14,6,(('انتقال دیده بان'!$AA$2:$AA$4926)+ROW('انتقال دیده بان'!$AA$2:$AA$4926)/100000000)/(('انتقال دیده بان'!$A$2:$A$4926<>"")* ('انتقال دیده بان'!$B$2:$B$4926<>"")* ISERROR(SEARCH("صندوق",'انتقال دیده بان'!$B$2:$B$4926))* ISERROR(SEARCH("درآمد ثابت",'انتقال دیده بان'!$B$2:$B$4926))* ISERROR(SEARCH("اختیار",'انتقال دیده بان'!$B$2:$B$4926))* ISERROR(SEARCH("اختيار",'انتقال دیده بان'!$B$2:$B$4926))* ISERROR(SEARCH("حق تقدم",'انتقال دیده بان'!$B$2:$B$4926))* ('انتقال دیده بان'!$AA$2:$AA$4926>=70)* ('انتقال دیده بان'!$J$2:$J$4926>=-0.5)* ('انتقال دیده بان'!$J$2:$J$4926<=1.5)* ('انتقال دیده بان'!$M$2:$M$4926>=-1)* ('انتقال دیده بان'!$M$2:$M$4926<=3.5)* ('انتقال دیده بان'!$D$2:$D$4926>=300000)* ('انتقال دیده بان'!$E$2:$E$4926>=1000000000)* ('انتقال دیده بان'!$Y$2:$Y$4926>=1)* IFERROR(('انتقال دیده بان'!$E$2:$E$4926/'انتقال دیده بان'!$C$2:$C$4926)>=20000000,FALSE)* ('انتقال دیده بان'!$AH$2:$AH$4926>=50)),ROWS($A$2:A7)),0),((('انتقال دیده بان'!$AA$2:$AA$4926)+ROW('انتقال دیده بان'!$AA$2:$AA$4926)/100000000)),0),"") | C7: =IF($B7="","",INDEX('انتقال دیده بان'!$A$2:$A$4926,$B7)) | D7: =IF($B7="","",INDEX('انتقال دیده بان'!$B$2:$B$4926,$B7)) | E7: =IF($B7="","",INDEX('انتقال دیده بان'!$AA$2:$AA$4926,$B7)) | F7: =IF($B7="","",INDEX('انتقال دیده بان'!$AJ$2:$AJ$4926,$B7)) | G7: =IF($B7="","",INDEX('انتقال دیده بان'!$J$2:$J$4926,$B7)) | H7: =IF($B7="","",INDEX('انتقال دیده بان'!$M$2:$M$4926,$B7)) | I7: =IF($B7="","",INDEX('انتقال دیده بان'!$D$2:$D$4926,$B7)) | J7: =IF($B7="","",INDEX('انتقال دیده بان'!$E$2:$E$4926,$B7)) | K7: =IF($B7="","",INDEX('انتقال دیده بان'!$Y$2:$Y$4926,$B7)) | L7: =IF($B7="","",INDEX('انتقال دیده بان'!$X$2:$X$4926,$B7)) | M7: =IF($B7="","",INDEX('انتقال دیده بان'!$AE$2:$AE$4926,$B7)) | N7: =IF($B7="","",INDEX('انتقال دیده بان'!$AF$2:$AF$4926,$B7)) | O7: =IF($B7="","",INDEX('انتقال دیده بان'!$AH$2:$AH$4926,$B7)) | P7: =IF($B7="","",INDEX('انتقال دیده بان'!$AI$2:$AI$4926,$B7)) | Q7: =IF($B7="","",IF($E7>=85,"شکار ممتاز",IF($E7>=80,"شکار قوی","شکار مشروط"))) | S7: هشدار | T7: کاندید نوسان‌گیری است؛ تأیید نهایی تابلو با معامله‌گر
A8: =IF($B8="","",ROWS($A$2:A8)) | B8: =IFERROR(MATCH(IFERROR(AGGREGATE(14,6,(('انتقال دیده بان'!$AA$2:$AA$4926)+ROW('انتقال دیده بان'!$AA$2:$AA$4926)/100000000)/(('انتقال دیده بان'!$A$2:$A$4926<>"")* ('انتقال دیده بان'!$B$2:$B$4926<>"")* ISERROR(SEARCH("صندوق",'انتقال دیده بان'!$B$2:$B$4926))* ISERROR(SEARCH("درآمد ثابت",'انتقال دیده بان'!$B$2:$B$4926))* ISERROR(SEARCH("اختیار",'انتقال دیده بان'!$B$2:$B$4926))* ISERROR(SEARCH("اختيار",'انتقال دیده بان'!$B$2:$B$4926))* ISERROR(SEARCH("حق تقدم",'انتقال دیده بان'!$B$2:$B$4926))* ('انتقال دیده بان'!$AA$2:$AA$4926>=70)* ('انتقال دیده بان'!$J$2:$J$4926>=-0.5)* ('انتقال دیده بان'!$J$2:$J$4926<=1.5)* ('انتقال دیده بان'!$M$2:$M$4926>=-1)* ('انتقال دیده بان'!$M$2:$M$4926<=3.5)* ('انتقال دیده بان'!$D$2:$D$4926>=300000)* ('انتقال دیده بان'!$E$2:$E$4926>=1000000000)* ('انتقال دیده بان'!$Y$2:$Y$4926>=1)* IFERROR(('انتقال دیده بان'!$E$2:$E$4926/'انتقال دیده بان'!$C$2:$C$4926)>=20000000,FALSE)* ('انتقال دیده بان'!$AH$2:$AH$4926>=50)),ROWS($A$2:A8)),0),((('انتقال دیده بان'!$AA$2:$AA$4926)+ROW('انتقال دیده بان'!$AA$2:$AA$4926)/100000000)),0),"") | C8: =IF($B8="","",INDEX('انتقال دیده بان'!$A$2:$A$4926,$B8)) | D8: =IF($B8="","",INDEX('انتقال دیده بان'!$B$2:$B$4926,$B8)) | E8: =IF($B8="","",INDEX('انتقال دیده بان'!$AA$2:$AA$4926,$B8)) | F8: =IF($B8="","",INDEX('انتقال دیده بان'!$AJ$2:$AJ$4926,$B8)) | G8: =IF($B8="","",INDEX('انتقال دیده بان'!$J$2:$J$4926,$B8)) | H8: =IF($B8="","",INDEX('انتقال دیده بان'!$M$2:$M$4926,$B8)) | I8: =IF($B8="","",INDEX('انتقال دیده بان'!$D$2:$D$4926,$B8)) | J8: =IF($B8="","",INDEX('انتقال دیده بان'!$E$2:$E$4926,$B8)) | K8: =IF($B8="","",INDEX('انتقال دیده بان'!$Y$2:$Y$4926,$B8)) | L8: =IF($B8="","",INDEX('انتقال دیده بان'!$X$2:$X$4926,$B8)) | M8: =IF($B8="","",INDEX('انتقال دیده بان'!$AE$2:$AE$4926,$B8)) | N8: =IF($B8="","",INDEX('انتقال دیده بان'!$AF$2:$AF$4926,$B8)) | O8: =IF($B8="","",INDEX('انتقال دیده بان'!$AH$2:$AH$4926,$B8)) | P8: =IF($B8="","",INDEX('انتقال دیده بان'!$AI$2:$AI$4926,$B8)) | Q8: =IF($B8="","",IF($E8>=85,"شکار ممتاز",IF($E8>=80,"شکار قوی","شکار مشروط"))) | S8: بروزرسانی | T8: پس از Refresh دیده بان، محاسبات خروجی با Excel دوباره محاسبه می‌شوند.
A9: =IF($B9="","",ROWS($A$2:A9)) | B9: =IFERROR(MATCH(IFERROR(AGGREGATE(14,6,(('انتقال دیده بان'!$AA$2:$AA$4926)+ROW('انتقال دیده بان'!$AA$2:$AA$4926)/100000000)/(('انتقال دیده بان'!$A$2:$A$4926<>"")* ('انتقال دیده بان'!$B$2:$B$4926<>"")* ISERROR(SEARCH("صندوق",'انتقال دیده بان'!$B$2:$B$4926))* ISERROR(SEARCH("درآمد ثابت",'انتقال دیده بان'!$B$2:$B$4926))* ISERROR(SEARCH("اختیار",'انتقال دیده بان'!$B$2:$B$4926))* ISERROR(SEARCH("اختيار",'انتقال دیده بان'!$B$2:$B$4926))* ISERROR(SEARCH("حق تقدم",'انتقال دیده بان'!$B$2:$B$4926))* ('انتقال دیده بان'!$AA$2:$AA$4926>=70)* ('انتقال دیده بان'!$J$2:$J$4926>=-0.5)* ('انتقال دیده بان'!$J$2:$J$4926<=1.5)* ('انتقال دیده بان'!$M$2:$M$4926>=-1)* ('انتقال دیده بان'!$M$2:$M$4926<=3.5)* ('انتقال دیده بان'!$D$2:$D$4926>=300000)* ('انتقال دیده بان'!$E$2:$E$4926>=1000000000)* ('انتقال دیده بان'!$Y$2:$Y$4926>=1)* IFERROR(('انتقال دیده بان'!$E$2:$E$4926/'انتقال دیده بان'!$C$2:$C$4926)>=20000000,FALSE)* ('انتقال دیده بان'!$AH$2:$AH$4926>=50)),ROWS($A$2:A9)),0),((('انتقال دیده بان'!$AA$2:$AA$4926)+ROW('انتقال دیده بان'!$AA$2:$AA$4926)/100000000)),0),"") | C9: =IF($B9="","",INDEX('انتقال دیده بان'!$A$2:$A$4926,$B9)) | D9: =IF($B9="","",INDEX('انتقال دیده بان'!$B$2:$B$4926,$B9)) | E9: =IF($B9="","",INDEX('انتقال دیده بان'!$AA$2:$AA$4926,$B9)) | F9: =IF($B9="","",INDEX('انتقال دیده بان'!$AJ$2:$AJ$4926,$B9)) | G9: =IF($B9="","",INDEX('انتقال دیده بان'!$J$2:$J$4926,$B9)) | H9: =IF($B9="","",INDEX('انتقال دیده بان'!$M$2:$M$4926,$B9)) | I9: =IF($B9="","",INDEX('انتقال دیده بان'!$D$2:$D$4926,$B9)) | J9: =IF($B9="","",INDEX('انتقال دیده بان'!$E$2:$E$4926,$B9)) | K9: =IF($B9="","",INDEX('انتقال دیده بان'!$Y$2:$Y$4926,$B9)) | L9: =IF($B9="","",INDEX('انتقال دیده بان'!$X$2:$X$4926,$B9)) | M9: =IF($B9="","",INDEX('انتقال دیده بان'!$AE$2:$AE$4926,$B9)) | N9: =IF($B9="","",INDEX('انتقال دیده بان'!$AF$2:$AF$4926,$B9)) | O9: =IF($B9="","",INDEX('انتقال دیده بان'!$AH$2:$AH$4926,$B9)) | P9: =IF($B9="","",INDEX('انتقال دیده بان'!$AI$2:$AI$4926,$B9)) | Q9: =IF($B9="","",IF($E9>=85,"شکار ممتاز",IF($E9>=80,"شکار قوی","شکار مشروط")))
A10: =IF($B10="","",ROWS($A$2:A10)) | B10: =IFERROR(MATCH(IFERROR(AGGREGATE(14,6,(('انتقال دیده بان'!$AA$2:$AA$4926)+ROW('انتقال دیده بان'!$AA$2:$AA$4926)/100000000)/(('انتقال دیده بان'!$A$2:$A$4926<>"")* ('انتقال دیده بان'!$B$2:$B$4926<>"")* ISERROR(SEARCH("صندوق",'انتقال دیده بان'!$B$2:$B$4926))* ISERROR(SEARCH("درآمد ثابت",'انتقال دیده بان'!$B$2:$B$4926))* ISERROR(SEARCH("اختیار",'انتقال دیده بان'!$B$2:$B$4926))* ISERROR(SEARCH("اختيار",'انتقال دیده بان'!$B$2:$B$4926))* ISERROR(SEARCH("حق تقدم",'انتقال دیده بان'!$B$2:$B$4926))* ('انتقال دیده بان'!$AA$2:$AA$4926>=70)* ('انتقال دیده بان'!$J$2:$J$4926>=-0.5)* ('انتقال دیده بان'!$J$2:$J$4926<=1.5)* ('انتقال دیده بان'!$M$2:$M$4926>=-1)* ('انتقال دیده بان'!$M$2:$M$4926<=3.5)* ('انتقال دیده بان'!$D$2:$D$4926>=300000)* ('انتقال دیده بان'!$E$2:$E$4926>=1000000000)* ('انتقال دیده بان'!$Y$2:$Y$4926>=1)* IFERROR(('انتقال دیده بان'!$E$2:$E$4926/'انتقال دیده بان'!$C$2:$C$4926)>=20000000,FALSE)* ('انتقال دیده بان'!$AH$2:$AH$4926>=50)),ROWS($A$2:A10)),0),((('انتقال دیده بان'!$AA$2:$AA$4926)+ROW('انتقال دیده بان'!$AA$2:$AA$4926)/100000000)),0),"") | C10: =IF($B10="","",INDEX('انتقال دیده بان'!$A$2:$A$4926,$B10)) | D10: =IF($B10="","",INDEX('انتقال دیده بان'!$B$2:$B$4926,$B10)) | E10: =IF($B10="","",INDEX('انتقال دیده بان'!$AA$2:$AA$4926,$B10)) | F10: =IF($B10="","",INDEX('انتقال دیده بان'!$AJ$2:$AJ$4926,$B10)) | G10: =IF($B10="","",INDEX('انتقال دیده بان'!$J$2:$J$4926,$B10)) | H10: =IF($B10="","",INDEX('انتقال دیده بان'!$M$2:$M$4926,$B10)) | I10: =IF($B10="","",INDEX('انتقال دیده بان'!$D$2:$D$4926,$B10)) | J10: =IF($B10="","",INDEX('انتقال دیده بان'!$E$2:$E$4926,$B10)) | K10: =IF($B10="","",INDEX('انتقال دیده بان'!$Y$2:$Y$4926,$B10)) | L10: =IF($B10="","",INDEX('انتقال دیده بان'!$X$2:$X$4926,$B10)) | M10: =IF($B10="","",INDEX('انتقال دیده بان'!$AE$2:$AE$4926,$B10)) | N10: =IF($B10="","",INDEX('انتقال دیده بان'!$AF$2:$AF$4926,$B10)) | O10: =IF($B10="","",INDEX('انتقال دیده بان'!$AH$2:$AH$4926,$B10)) | P10: =IF($B10="","",INDEX('انتقال دیده بان'!$AI$2:$AI$4926,$B10)) | Q10: =IF($B10="","",IF($E10>=85,"شکار ممتاز",IF($E10>=80,"شکار قوی","شکار مشروط")))
A11: =IF($B11="","",ROWS($A$2:A11)) | B11: =IFERROR(MATCH(IFERROR(AGGREGATE(14,6,(('انتقال دیده بان'!$AA$2:$AA$4926)+ROW('انتقال دیده بان'!$AA$2:$AA$4926)/100000000)/(('انتقال دیده بان'!$A$2:$A$4926<>"")* ('انتقال دیده بان'!$B$2:$B$4926<>"")* ISERROR(SEARCH("صندوق",'انتقال دیده بان'!$B$2:$B$4926))* ISERROR(SEARCH("درآمد ثابت",'انتقال دیده بان'!$B$2:$B$4926))* ISERROR(SEARCH("اختیار",'انتقال دیده بان'!$B$2:$B$4926))* ISERROR(SEARCH("اختيار",'انتقال دیده بان'!$B$2:$B$4926))* ISERROR(SEARCH("حق تقدم",'انتقال دیده بان'!$B$2:$B$4926))* ('انتقال دیده بان'!$AA$2:$AA$4926>=70)* ('انتقال دیده بان'!$J$2:$J$4926>=-0.5)* ('انتقال دیده بان'!$J$2:$J$4926<=1.5)* ('انتقال دیده بان'!$M$2:$M$4926>=-1)* ('انتقال دیده بان'!$M$2:$M$4926<=3.5)* ('انتقال دیده بان'!$D$2:$D$4926>=300000)* ('انتقال دیده بان'!$E$2:$E$4926>=1000000000)* ('انتقال دیده بان'!$Y$2:$Y$4926>=1)* IFERROR(('انتقال دیده بان'!$E$2:$E$4926/'انتقال دیده بان'!$C$2:$C$4926)>=20000000,FALSE)* ('انتقال دیده بان'!$AH$2:$AH$4926>=50)),ROWS($A$2:A11)),0),((('انتقال دیده بان'!$AA$2:$AA$4926)+ROW('انتقال دیده بان'!$AA$2:$AA$4926)/100000000)),0),"") | C11: =IF($B11="","",INDEX('انتقال دیده بان'!$A$2:$A$4926,$B11)) | D11: =IF($B11="","",INDEX('انتقال دیده بان'!$B$2:$B$4926,$B11)) | E11: =IF($B11="","",INDEX('انتقال دیده بان'!$AA$2:$AA$4926,$B11)) | F11: =IF($B11="","",INDEX('انتقال دیده بان'!$AJ$2:$AJ$4926,$B11)) | G11: =IF($B11="","",INDEX('انتقال دیده بان'!$J$2:$J$4926,$B11)) | H11: =IF($B11="","",INDEX('انتقال دیده بان'!$M$2:$M$4926,$B11)) | I11: =IF($B11="","",INDEX('انتقال دیده بان'!$D$2:$D$4926,$B11)) | J11: =IF($B11="","",INDEX('انتقال دیده بان'!$E$2:$E$4926,$B11)) | K11: =IF($B11="","",INDEX('انتقال دیده بان'!$Y$2:$Y$4926,$B11)) | L11: =IF($B11="","",INDEX('انتقال دیده بان'!$X$2:$X$4926,$B11)) | M11: =IF($B11="","",INDEX('انتقال دیده بان'!$AE$2:$AE$4926,$B11)) | N11: =IF($B11="","",INDEX('انتقال دیده بان'!$AF$2:$AF$4926,$B11)) | O11: =IF($B11="","",INDEX('انتقال دیده بان'!$AH$2:$AH$4926,$B11)) | P11: =IF($B11="","",INDEX('انتقال دیده بان'!$AI$2:$AI$4926,$B11)) | Q11: =IF($B11="","",IF($E11>=85,"شکار ممتاز",IF($E11>=80,"شکار قوی","شکار مشروط")))
